<?xml version="1.0"?>
<robot name="hsrb"
       xmlns:xi="http://www.w3.org/2001/XInclude">
  <link name="base_footprint">
  </link>
  <link name="base_x_link">
    <inertial>
      <mass value="0" />
      <origin xyz="0 0 0" rpy="0 -0 0"/>
      <inertia ixx="0" ixy="0" ixz="0" iyy="0" iyz="0" izz="0"/>
    </inertial>
  </link>
  <link name="base_y_link">
    <inertial>
      <mass value="0" />
      <origin xyz="0 0 0" rpy="0 -0 0"/>
      <inertia ixx="0" ixy="0" ixz="0" iyy="0" iyz="0" izz="0"/>
    </inertial>
  </link>
  <link name="base_link">
    <visual>
      <origin xyz="0 0 0" rpy="0 -0 0"/>
      <geometry>
        <mesh filename="file:///tmp/base_link_mesh.dae" scale="1 1 1" />
      </geometry>
    </visual>
    <collision>
      <origin xyz="0 0 0" rpy="0 -0 0"/>
      <geometry>
        <mesh filename="file:///tmp/base_link_mesh.dae" scale="1 1 1" />
      </geometry>
    </collision>
    <inertial>
      <mass value="50" />
      <origin xyz="-0.025978 -0.005498 0.17633" rpy="0 -0 0"/>
      <inertia ixx="0.3742" ixy="0.000434172" ixz="0.03088" iyy="0.3436" iyz="0.01775" izz="0.1509"/>
    </inertial>
  </link>
  <link name="arm_lift_link">
    <visual>
      <origin xyz="0 0 0" rpy="0 -0 0"/>
      <geometry>
        <mesh filename="file:///tmp/arm_lift_link_mesh.dae" scale="1 1 1" />
      </geometry>
    </visual>
    <collision>
      <origin xyz="0 0 0" rpy="0 -0 0"/>
      <geometry>
        <mesh filename="file:///tmp/arm_lift_link_mesh.dae" scale="1 1 1" />
      </geometry>
    </collision>
    <inertial>
      <mass value="1.27582" />
      <origin xyz="0.051549 0.042438 -0.064145" rpy="0 -0 0"/>
      <inertia ixx="0.004633" ixy="0.000475273" ixz="-0.002403" iyy="0.008065" iyz="-0.000100269" izz="0.007672"/>
    </inertial>
  </link>
  <link name="arm_flex_link">
    <visual>
      <origin xyz="0 0 0" rpy="0 -0 0"/>
      <geometry>
        <mesh filename="file:///tmp/arm_flex_link_mesh.dae" scale="1 1 1" />
      </geometry>
    </visual>
    <collision>
      <origin xyz="0 0 0" rpy="0 -0 0"/>
      <geometry>
        <mesh filename="file:///tmp/arm_flex_link_mesh.dae" scale="1 1 1" />
      </geometry>
    </collision>
    <inertial>
      <mass value="1.33929" />
      <origin xyz="0.000632 0.006404 0.118529" rpy="0 -0 0"/>
      <inertia ixx="7.528" ixy="-2.02842e-05" ixz="-2.29472e-05" iyy="0.007102" iyz="-9.17961e-05" izz="0.001552"/>
    </inertial>
  </link>
  <link name="arm_roll_link">
    <visual>
      <origin xyz="0 0 0" rpy="0 -0 0"/>
      <geometry>
        <mesh filename="file:///tmp/arm_roll_link_mesh.dae" scale="1 1 1" />
      </geometry>
    </visual>
    <collision>
      <origin xyz="0 0 0" rpy="0 -0 0"/>
      <geometry>
        <mesh filename="file:///tmp/arm_roll_link_mesh.dae" scale="1 1 1" />
      </geometry>
    </collision>
    <inertial>
      <mass value="0.247936" />
      <origin xyz="-0.006927 0.002039 -0.064837" rpy="0 -0 0"/>
      <inertia ixx="0.004267" ixy="-1.83222e-05" ixz="1.79845e-05" iyy="0.000780924" iyz="-1.39233e-05" izz="0.00412"/>
    </inertial>
  </link>
  <link name="wrist_flex_link">
    <visual>
      <origin xyz="0 0 0" rpy="0 -0 0"/>
      <geometry>
        <mesh filename="file:///tmp/wrist_flex_link_mesh.dae" scale="1 1 1" />
      </geometry>
    </visual>
    <collision>
      <origin xyz="0 0 0.03" rpy="0 -0 0"/>
      <geometry>
        <mesh filename="file:///tmp/wrist_flex_link_mesh.dae" scale="1 1 1" />
      </geometry>
    </collision>
    <inertial>
      <mass value="0.681225" />
      <origin xyz="0.000131 -0.003929 0.00217" rpy="0 -0 0"/>
      <inertia ixx="7.43536e-05" ixy="4.94515e-07" ixz="2.2937e-08" iyy="3.84329e-05" iyz="-2.55576e-06" izz="6.46809e-05"/>
    </inertial>
  </link>
  <link name="wrist_roll_link">
    <visual>
      <origin xyz="0 0 0" rpy="0 -0 0"/>
      <geometry>
        <mesh filename="file:///tmp/wrist_roll_link_mesh.dae" scale="1 1 1" />
      </geometry>
    </visual>
    <collision>
      <origin xyz="0 0 0" rpy="0 -0 0"/>
      <geometry>
        <mesh filename="file:///tmp/wrist_roll_link_mesh.dae" scale="1 1 1" />
      </geometry>
    </collision>
    <inertial>
      <mass value="0.761692" />
      <origin xyz="-0.001416 -0.001547 0.081689" rpy="0 -0 0"/>
      <inertia ixx="0.000805634" ixy="-1.44318e-05" ixz="2.82047e-05" iyy="0.000768077" iyz="2.24602e-05" izz="0.000453407"/>
    </inertial>
  </link>
  <link name="hand_palm_link">
    <visual>
      <origin xyz="0 0 0" rpy="0 -0 0"/>
      <geometry>
        <mesh filename="file:///tmp/hand_palm_link_mesh.dae" scale="1 1 1" />
      </geometry>
    </visual>
    <collision>
      <origin xyz="0 0 0" rpy="0 -0 0"/>
      <geometry>
        <mesh filename="file:///tmp/hand_palm_link_mesh.dae" scale="1 1 1" />
      </geometry>
    </collision>
    <inertial>
      <mass value="0.15" />
      <origin xyz="0 0 0" rpy="0 -0 0"/>
      <inertia ixx="0.015" ixy="0" ixz="0" iyy="0.015" iyz="0" izz="0.015"/>
    </inertial>
  </link>
  <link name="hand_camera_frame">
  </link>
  <link name="hand_camera_gazebo_frame">
  </link>
  <link name="hand_l_proximal_link">
    <inertial>
      <mass value="0.001" />
      <origin xyz="0 0 0" rpy="0 -0 0"/>
      <inertia ixx="0.00015" ixy="0" ixz="0" iyy="0.00015" iyz="0" izz="0.00015"/>
    </inertial>
  </link>
  <link name="hand_l_spring_proximal_link">
    <visual>
      <origin xyz="0 0 0" rpy="0 -0 0"/>
      <geometry>
        <mesh filename="file:///tmp/hand_l_spring_proximal_link_mesh.dae" scale="1 1 1" />
      </geometry>
    </visual>
    <collision>
      <origin xyz="0 0 0" rpy="0 -0 0"/>
      <geometry>
        <mesh filename="file:///tmp/hand_l_spring_proximal_link_mesh.dae" scale="1 1 1" />
      </geometry>
    </collision>
    <inertial>
      <mass value="0.043589" />
      <origin xyz="0.021418 0.00248 0.022688" rpy="0 -0 0"/>
      <inertia ixx="2.60339e-05" ixy="-1.44078e-07" ixz="-1.98241e-06" iyy="2.88248e-05" iyz="-1.26842e-06" izz="5.13592e-06"/>
    </inertial>
  </link>
  <link name="hand_l_mimic_distal_link">
    <inertial>
      <mass value="0.001" />
      <origin xyz="0 0 0" rpy="0 -0 0"/>
      <inertia ixx="0.00015" ixy="0" ixz="0" iyy="0.00015" iyz="0" izz="0.00015"/>
    </inertial>
  </link>
  <link name="hand_l_distal_link">
    <visual>
      <origin xyz="0 0 0" rpy="0 -0 0"/>
      <geometry>
        <mesh filename="file:///tmp/hand_l_distal_link_mesh.dae" scale="1 1 1" />
      </geometry>
    </visual>
    <collision>
      <origin xyz="0 0 0" rpy="0 -0 0"/>
      <geometry>
        <mesh filename="file:///tmp/hand_l_distal_link_mesh.dae" scale="1 1 1" />
      </geometry>
    </collision>
    <inertial>
      <mass value="0.027731" />
      <origin xyz="0.011116 0.005679 0.017532" rpy="0 -0 0"/>
      <inertia ixx="4.45195e-06" ixy="-6.17574e-07" ixz="5.03765e-07" iyy="5.03765e-07" iyz="-4.35048e-07" izz="4.45676e-06"/>
    </inertial>
  </link>
  <link name="hand_l_finger_tip_frame">
    <inertial>
      <mass value="0.001" />
      <origin xyz="0 0 0" rpy="0 -0 0"/>
      <inertia ixx="0.00015" ixy="0" ixz="0" iyy="0.00015" iyz="0" izz="0.00015"/>
    </inertial>
  </link>
  <link name="hand_l_finger_vacuum_frame">
    <visual>
      <origin xyz="0 0 -0.01" rpy="0 -0 0"/>
      <geometry>
      </geometry>
    </visual>
    <inertial>
      <mass value="0.001" />
      <origin xyz="0 0 0" rpy="0 -0 0"/>
      <inertia ixx="0.00015" ixy="0" ixz="0" iyy="0.00015" iyz="0" izz="0.00015"/>
    </inertial>
  </link>
  <link name="hand_motor_dummy_link">
    <inertial>
      <mass value="0.001" />
      <origin xyz="0 0 0" rpy="0 -0 0"/>
      <inertia ixx="0.00015" ixy="0" ixz="0" iyy="0.00015" iyz="0" izz="0.00015"/>
    </inertial>
  </link>
  <link name="hand_r_proximal_link">
    <inertial>
      <mass value="0.001" />
      <origin xyz="0 0 0" rpy="0 -0 0"/>
      <inertia ixx="0.00015" ixy="0" ixz="0" iyy="0.00015" iyz="0" izz="0.00015"/>
    </inertial>
  </link>
  <link name="hand_r_spring_proximal_link">
    <visual>
      <origin xyz="0 0 0" rpy="0 -0 0"/>
      <geometry>
        <mesh filename="file:///tmp/hand_r_spring_proximal_link_mesh.dae" scale="1 1 1" />
      </geometry>
    </visual>
    <collision>
      <origin xyz="0 0 0" rpy="0 -0 0"/>
      <geometry>
        <mesh filename="file:///tmp/hand_r_spring_proximal_link_mesh.dae" scale="1 1 1" />
      </geometry>
    </collision>
    <inertial>
      <mass value="0.043956" />
      <origin xyz="0.013203 0.002096 0.023311" rpy="0 -0 0"/>
      <inertia ixx="2.62366e-05" ixy="1.631e-08" ixz="1.28184e-06" iyy="2.88382e-05" iyz="-1.62171e-06" izz="4.95715e-06"/>
    </inertial>
  </link>
  <link name="hand_r_mimic_distal_link">
    <inertial>
      <mass value="0.001" />
      <origin xyz="0 0 0" rpy="0 -0 0"/>
      <inertia ixx="0.00015" ixy="0" ixz="0" iyy="0.00015" iyz="0" izz="0.00015"/>
    </inertial>
  </link>
  <link name="hand_r_distal_link">
    <visual>
      <origin xyz="0 0 0" rpy="0 -0 0"/>
      <geometry>
        <mesh filename="file:///tmp/hand_r_distal_link_mesh.dae" scale="1 1 1" />
      </geometry>
    </visual>
    <collision>
      <origin xyz="0 0 0" rpy="0 -0 0"/>
      <geometry>
        <mesh filename="file:///tmp/hand_r_distal_link_mesh.dae" scale="1 1 1" />
      </geometry>
    </collision>
    <inertial>
      <mass value="0.020927" />
      <origin xyz="0.014256 -0.008321 0.015591" rpy="0 -0 0"/>
      <inertia ixx="3.07518e-06" ixy="-4.954e-08" ixz="9.481e-09" iyy="4.07408e-06" iyz="8.43648e-07" izz="2.8078e-06"/>
    </inertial>
  </link>
  <link name="hand_r_finger_tip_frame">
    <inertial>
      <mass value="0.001" />
      <origin xyz="0 0 0" rpy="0 -0 0"/>
      <inertia ixx="0.00015" ixy="0" ixz="0" iyy="0.00015" iyz="0" izz="0.00015"/>
    </inertial>
  </link>
  <link name="wrist_ft_sensor_frame">
  </link>
  <link name="base_imu_frame">
  </link>
  <link name="base_range_sensor_link">
    <visual>
      <origin xyz="0 0 0" rpy="0 -0 0"/>
      <geometry>
        <mesh filename="file:///tmp/base_range_sensor_link_mesh.dae" scale="1 1 1" />
      </geometry>
    </visual>
    <collision>
      <origin xyz="0 0 0" rpy="0 -0 0"/>
      <geometry>
        <mesh filename="file:///tmp/base_range_sensor_link_mesh.dae" scale="1 1 1" />
      </geometry>
    </collision>
  </link>
  <link name="base_roll_link">
    <inertial>
      <mass value="10.2394" />
      <origin xyz="-0.019482 0.002191 0.071013" rpy="0 -0 0"/>
      <inertia ixx="0.07671" ixy="-0.01005" ixz="0.001749" iyy="0.09057" iyz="0.001549" izz="0.145"/>
    </inertial>
  </link>
  <link name="base_l_drive_wheel_link">
    <visual>
      <origin xyz="0 0 0" rpy="1.5708 -0 0"/>
      <geometry>
      </geometry>
    </visual>
    <collision>
      <origin xyz="0 0 0" rpy="1.5708 -0 0"/>
      <geometry>
      </geometry>
    </collision>
    <inertial>
      <mass value="0.2" />
      <origin xyz="0 0 0" rpy="0 -0 0"/>
      <inertia ixx="0.015" ixy="0" ixz="0" iyy="0.015" iyz="0" izz="0.015"/>
    </inertial>
  </link>
  <link name="base_l_passive_wheel_x_frame">
    <inertial>
      <mass value="0.2" />
      <origin xyz="0 0 0" rpy="0 -0 0"/>
      <inertia ixx="0.015" ixy="0" ixz="0" iyy="0.015" iyz="0" izz="0.015"/>
    </inertial>
  </link>
  <link name="base_l_passive_wheel_y_frame">
    <inertial>
      <mass value="0.2" />
      <origin xyz="0 0 0" rpy="0 -0 0"/>
      <inertia ixx="0.015" ixy="0" ixz="0" iyy="0.015" iyz="0" izz="0.015"/>
    </inertial>
  </link>
  <link name="base_l_passive_wheel_z_link">
    <visual>
      <origin xyz="0 0 0" rpy="0 -0 0"/>
      <geometry>
      </geometry>
    </visual>
    <collision>
      <origin xyz="0 0 0" rpy="0 -0 0"/>
      <geometry>
      </geometry>
    </collision>
    <inertial>
      <mass value="0.2" />
      <origin xyz="0 0 0" rpy="0 -0 0"/>
      <inertia ixx="0.015" ixy="0" ixz="0" iyy="0.015" iyz="0" izz="0.015"/>
    </inertial>
  </link>
  <link name="base_r_drive_wheel_link">
    <visual>
      <origin xyz="0 0 0" rpy="1.5708 -0 0"/>
      <geometry>
      </geometry>
    </visual>
    <collision>
      <origin xyz="0 0 0" rpy="1.5708 -0 0"/>
      <geometry>
      </geometry>
    </collision>
    <inertial>
      <mass value="0.2" />
      <origin xyz="0 0 0" rpy="0 -0 0"/>
      <inertia ixx="0.015" ixy="0" ixz="0" iyy="0.015" iyz="0" izz="0.015"/>
    </inertial>
  </link>
  <link name="base_r_passive_wheel_x_frame">
    <inertial>
      <mass value="0.2" />
      <origin xyz="0 0 0" rpy="0 -0 0"/>
      <inertia ixx="0.015" ixy="0" ixz="0" iyy="0.015" iyz="0" izz="0.015"/>
    </inertial>
  </link>
  <link name="base_r_passive_wheel_y_frame">
    <inertial>
      <mass value="0.2" />
      <origin xyz="0 0 0" rpy="0 -0 0"/>
      <inertia ixx="0.015" ixy="0" ixz="0" iyy="0.015" iyz="0" izz="0.015"/>
    </inertial>
  </link>
  <link name="base_r_passive_wheel_z_link">
    <visual>
      <origin xyz="0 0 0" rpy="0 -0 0"/>
      <geometry>
      </geometry>
    </visual>
    <collision>
      <origin xyz="0 0 0" rpy="0 -0 0"/>
      <geometry>
      </geometry>
    </collision>
    <inertial>
      <mass value="0.2" />
      <origin xyz="0 0 0" rpy="0 -0 0"/>
      <inertia ixx="0.015" ixy="0" ixz="0" iyy="0.015" iyz="0" izz="0.015"/>
    </inertial>
  </link>
  <link name="torso_lift_link">
    <visual>
      <origin xyz="0 0 0" rpy="0 -0 0"/>
      <geometry>
        <mesh filename="file:///tmp/torso_lift_link_mesh.dae" scale="1 1 1" />
      </geometry>
    </visual>
    <collision>
      <origin xyz="0 0 0" rpy="0 -0 0"/>
      <geometry>
        <mesh filename="file:///tmp/torso_lift_link_mesh.dae" scale="1 1 1" />
      </geometry>
    </collision>
    <inertial>
      <mass value="3.42078" />
      <origin xyz="-0.051142 0.003454 -0.2905" rpy="0 -0 0"/>
      <inertia ixx="0.1045" ixy="-0.000460885" ixz="0.00010113" iyy="0.105" iyz="0.002941" izz="0.01284"/>
    </inertial>
  </link>
  <link name="head_pan_link">
    <visual>
      <origin xyz="0 0 0" rpy="0 -0 0"/>
      <geometry>
        <mesh filename="file:///tmp/head_pan_link_mesh.dae" scale="1 1 1" />
      </geometry>
    </visual>
    <collision>
      <origin xyz="0 0 0" rpy="0 -0 0"/>
      <geometry>
        <mesh filename="file:///tmp/head_pan_link_mesh.dae" scale="1 1 1" />
      </geometry>
    </collision>
    <inertial>
      <mass value="0.571903" />
      <origin xyz="0.001724 -0.001969 -0.028886" rpy="0 -0 0"/>
      <inertia ixx="0.000971142" ixy="6.17949e-05" ixz="-0.000113923" iyy="0.000653355" iyz="6.90363e-05" izz="0.000765203"/>
    </inertial>
  </link>
  <link name="head_tilt_link">
    <visual>
      <origin xyz="0 0 0" rpy="0 -0 0"/>
      <geometry>
        <mesh filename="file:///tmp/head_tilt_link_mesh.dae" scale="1 1 1" />
      </geometry>
    </visual>
    <collision>
      <origin xyz="0 0 0" rpy="0 -0 0"/>
      <geometry>
        <mesh filename="file:///tmp/head_tilt_link_mesh.dae" scale="1 1 1" />
      </geometry>
    </collision>
    <inertial>
      <mass value="2.1238" />
      <origin xyz="-0.055376 -0.002436 0.117733" rpy="0 -0 0"/>
      <inertia ixx="0.01941" ixy="-0.000138091" ixz="0.005035" iyy="0.01498" iyz="8.74925e-05" izz="0.01167"/>
    </inertial>
  </link>
  <link name="head_center_camera_frame">
  </link>
  <link name="head_center_camera_gazebo_frame">
  </link>
  <link name="head_l_stereo_camera_link">
    <visual>
      <origin xyz="0 0 0" rpy="0 -0 0"/>
      <geometry>
        <mesh filename="file:///tmp/head_l_stereo_camera_link_mesh.dae" scale="1 1 1" />
      </geometry>
    </visual>
  </link>
  <link name="head_l_stereo_camera_gazebo_frame">
  </link>
  <link name="head_r_stereo_camera_link">
    <visual>
      <origin xyz="0 0 0" rpy="0 -0 0"/>
      <geometry>
        <mesh filename="file:///tmp/head_r_stereo_camera_link_mesh.dae" scale="1 1 1" />
      </geometry>
    </visual>
  </link>
  <link name="head_r_stereo_camera_gazebo_frame">
  </link>
  <link name="head_rgbd_sensor_link">
    <visual>
      <origin xyz="0 0 0" rpy="0 -0 0"/>
      <geometry>
        <mesh filename="file:///tmp/head_rgbd_sensor_link_mesh.dae" scale="1 1 1" />
      </geometry>
    </visual>
    <collision>
      <origin xyz="0 0 0" rpy="0 -0 0"/>
      <geometry>
        <mesh filename="file:///tmp/head_rgbd_sensor_link_mesh.dae" scale="1 1 1" />
      </geometry>
    </collision>
  </link>
  <link name="head_rgbd_sensor_gazebo_frame">
  </link>
  <joint name="base_x_joint" type="prismatic">
    <parent link="base_footprint"/>
    <child  link="base_x_link"/>
    <origin xyz="0 0 0" rpy="0 -0 0 "/>
    <axis   xyz="1 0 0"/>
    <limit lower="-10" upper="10" effort="300" velocity="0.2" />
    <dynamics damping="0.2" friction="0" />
  </joint>
  <joint name="base_y_joint" type="prismatic">
    <parent link="base_x_link"/>
    <child  link="base_y_link"/>
    <origin xyz="0 0 0" rpy="0 -0 0 "/>
    <axis   xyz="0 1 0"/>
    <limit lower="-10" upper="10" effort="300" velocity="0.2" />
    <dynamics damping="0.2" friction="0" />
  </joint>
  <joint name="base_t_joint" type="revolute">
    <parent link="base_y_link"/>
    <child  link="base_link"/>
    <origin xyz="0 0 0" rpy="0 -0 0 "/>
    <axis   xyz="0 0 1"/>
    <limit lower="-10" upper="10" effort="300" velocity="0.2" />
    <dynamics damping="0.2" friction="0" />
  </joint>
  <joint name="arm_lift_joint" type="prismatic">
    <parent link="base_link"/>
    <child  link="arm_lift_link"/>
    <origin xyz="0 0 0.34" rpy="0 -0 0 "/>
    <axis   xyz="0 0 1"/>
    <limit lower="0" upper="0.69" effort="300" velocity="0.2" />
    <dynamics damping="1" friction="0" />
  </joint>
  <joint name="arm_flex_joint" type="revolute">
    <parent link="arm_lift_link"/>
    <child  link="arm_flex_link"/>
    <origin xyz="0.141 0.078 0" rpy="0 -0 0 "/>
    <axis   xyz="0 -1 0"/>
    <limit lower="-2.62" upper="0" effort="100" velocity="1.2" />
    <dynamics damping="1" friction="0" />
  </joint>
  <joint name="arm_roll_joint" type="revolute">
    <parent link="arm_flex_link"/>
    <child  link="arm_roll_link"/>
    <origin xyz="0.005 0 0.345" rpy="0 -0 0 "/>
    <axis   xyz="0 0 1"/>
    <limit lower="-2.09" upper="3.84" effort="100" velocity="2" />
    <dynamics damping="0.1" friction="0" />
  </joint>
  <joint name="wrist_flex_joint" type="revolute">
    <parent link="arm_roll_link"/>
    <child  link="wrist_flex_link"/>
    <origin xyz="0 0 0" rpy="0 -0 0 "/>
    <axis   xyz="0 -1 0"/>
    <limit lower="-1.92" upper="1.22" effort="100" velocity="1.5" />
    <dynamics damping="1" friction="0" />
  </joint>
  <joint name="wrist_roll_joint" type="revolute">
    <parent link="wrist_flex_link"/>
    <child  link="wrist_roll_link"/>
    <origin xyz="0 0 0" rpy="0 -0 0 "/>
    <axis   xyz="0 0 1"/>
    <limit lower="-1.92" upper="3.67" effort="100" velocity="1.5" />
    <dynamics damping="1" friction="0" />
  </joint>
  <joint name="hand_palm_joint" type="fixed">
    <parent link="wrist_roll_link"/>
    <child  link="hand_palm_link"/>
    <origin xyz="0.012 0 0.1405" rpy="0 -0 -3.14159 "/>
    <axis   xyz="0 0 0"/>
    <dynamics damping="0.2" friction="0" />
  </joint>
  <joint name="hand_camera_frame_joint" type="fixed">
    <parent link="hand_palm_link"/>
    <child  link="hand_camera_frame"/>
    <origin xyz="0.039 0 -0.0045" rpy="0 -0 0 "/>
    <axis   xyz="0 0 0"/>
    <dynamics damping="0.2" friction="0" />
  </joint>
  <joint name="hand_camera_gazebo_frame_joint" type="fixed">
    <parent link="hand_camera_frame"/>
    <child  link="hand_camera_gazebo_frame"/>
    <origin xyz="0 0 0" rpy="0 -1.5708 1.5708 "/>
    <axis   xyz="0 0 0"/>
    <dynamics damping="0.2" friction="0" />
  </joint>
  <joint name="hand_l_proximal_joint" type="revolute">
    <parent link="hand_palm_link"/>
    <child  link="hand_l_proximal_link"/>
    <origin xyz="-0.01675 -0.0245 -0.0175" rpy="0 -0 0 "/>
    <axis   xyz="1 0 0"/>
    <limit lower="-0.798" upper="1.24" effort="100" velocity="1" />
    <dynamics damping="0.0001" friction="0" />
  </joint>
  <joint name="hand_l_spring_proximal_joint" type="revolute">
    <parent link="hand_l_proximal_link"/>
    <child  link="hand_l_spring_proximal_link"/>
    <origin xyz="0 0 0" rpy="0 -0 0 "/>
    <axis   xyz="1 0 0"/>
    <limit lower="0" upper="0.698" effort="10" velocity="1" />
    <dynamics damping="0.0001" friction="0" />
  </joint>
  <joint name="hand_l_mimic_distal_joint" type="revolute">
    <parent link="hand_l_spring_proximal_link"/>
    <child  link="hand_l_mimic_distal_link"/>
    <origin xyz="0 0 0.07" rpy="0 -0 0 "/>
    <axis   xyz="1 0 0"/>
    <limit lower="-0.698" upper="-0" effort="100" velocity="1" />
    <dynamics damping="0.0001" friction="0" />
  </joint>
  <joint name="hand_l_distal_joint" type="revolute">
    <parent link="hand_l_mimic_distal_link"/>
    <child  link="hand_l_distal_link"/>
    <origin xyz="0 0 0" rpy="0 -0 0 "/>
    <axis   xyz="1 0 0"/>
    <limit lower="-1.24" upper="0.798" effort="100" velocity="1" />
    <dynamics damping="0.0001" friction="0" />
  </joint>
  <joint name="hand_l_finger_tip_frame_joint" type="fixed">
    <parent link="hand_l_distal_link"/>
    <child  link="hand_l_finger_tip_frame"/>
    <origin xyz="0.01675 0.0193 0.0379" rpy="-1.5708 0 0 "/>
    <axis   xyz="0 0 0"/>
    <dynamics damping="0.0001" friction="0" />
  </joint>
  <joint name="hand_l_finger_vacuum_frame_joint" type="fixed">
    <parent link="hand_l_distal_link"/>
    <child  link="hand_l_finger_vacuum_frame"/>
    <origin xyz="0.00475 -0.011539 0.03322" rpy="0.785398 -0 0 "/>
    <axis   xyz="0 0 0"/>
    <dynamics damping="0.2" friction="0" />
  </joint>
  <joint name="hand_motor_joint" type="revolute">
    <parent link="hand_palm_link"/>
    <child  link="hand_motor_dummy_link"/>
    <origin xyz="0 0 0" rpy="0 -0 0 "/>
    <axis   xyz="1 0 0"/>
    <limit lower="-0.798" upper="1.24" effort="100" velocity="1" />
    <dynamics damping="0.0001" friction="0" />
  </joint>
  <joint name="hand_r_proximal_joint" type="revolute">
    <parent link="hand_palm_link"/>
    <child  link="hand_r_proximal_link"/>
    <origin xyz="-0.01675 0.0245 -0.0175" rpy="0 -0 0 "/>
    <axis   xyz="-1 0 0"/>
    <limit lower="-0.798" upper="1.24" effort="100" velocity="1" />
    <dynamics damping="0.0001" friction="0" />
  </joint>
  <joint name="hand_r_spring_proximal_joint" type="revolute">
    <parent link="hand_r_proximal_link"/>
    <child  link="hand_r_spring_proximal_link"/>
    <origin xyz="0 0 0" rpy="0 -0 0 "/>
    <axis   xyz="-1 0 0"/>
    <limit lower="0" upper="0.698" effort="10" velocity="1" />
    <dynamics damping="0.0001" friction="0" />
  </joint>
  <joint name="hand_r_mimic_distal_joint" type="revolute">
    <parent link="hand_r_spring_proximal_link"/>
    <child  link="hand_r_mimic_distal_link"/>
    <origin xyz="0 0 0.07" rpy="0 -0 0 "/>
    <axis   xyz="-1 0 0"/>
    <limit lower="-0.698" upper="-0" effort="100" velocity="1" />
    <dynamics damping="0.0001" friction="0" />
  </joint>
  <joint name="hand_r_distal_joint" type="revolute">
    <parent link="hand_r_mimic_distal_link"/>
    <child  link="hand_r_distal_link"/>
    <origin xyz="0 0 0" rpy="0 -0 0 "/>
    <axis   xyz="-1 0 0"/>
    <limit lower="-1.24" upper="0.798" effort="100" velocity="1" />
    <dynamics damping="0.0001" friction="0" />
  </joint>
  <joint name="hand_r_finger_tip_frame_joint" type="fixed">
    <parent link="hand_r_distal_link"/>
    <child  link="hand_r_finger_tip_frame"/>
    <origin xyz="0.01675 -0.0193 0.0379" rpy="1.5708 -0 0 "/>
    <axis   xyz="0 0 0"/>
    <dynamics damping="0.2" friction="0" />
  </joint>
  <joint name="wrist_ft_sensor_frame_joint" type="fixed">
    <parent link="wrist_roll_link"/>
    <child  link="wrist_ft_sensor_frame"/>
    <origin xyz="0 0 0.0735" rpy="-3.14159 -0 0 "/>
    <axis   xyz="0 0 0"/>
    <dynamics damping="0.2" friction="0" />
  </joint>
  <joint name="base_imu_frame_joint" type="fixed">
    <parent link="base_link"/>
    <child  link="base_imu_frame"/>
    <origin xyz="0.0005 0.1296 0.181" rpy="0 -0 0 "/>
    <axis   xyz="0 0 0"/>
    <dynamics damping="0.2" friction="0" />
  </joint>
  <joint name="base_range_sensor_joint" type="fixed">
    <parent link="base_link"/>
    <child  link="base_range_sensor_link"/>
    <origin xyz="0.1675 0 0.1844" rpy="0 -0 0 "/>
    <axis   xyz="0 0 0"/>
    <dynamics damping="0.2" friction="0" />
  </joint>
  <joint name="base_roll_joint" type="continuous">
    <parent link="base_link"/>
    <child  link="base_roll_link"/>
    <origin xyz="0 0 0" rpy="0 -0 0 "/>
    <axis   xyz="0 0 1"/>
    <limit lower="0" upper="0" effort="34.46" velocity="2.5" />
    <dynamics damping="0.7" friction="0" />
  </joint>
  <joint name="base_l_drive_wheel_joint" type="continuous">
    <parent link="base_roll_link"/>
    <child  link="base_l_drive_wheel_link"/>
    <origin xyz="-0.11 0.133 0.04" rpy="0 -0 0 "/>
    <axis   xyz="0 1 0"/>
    <limit lower="0" upper="0" effort="11.067" velocity="20.8" />
    <dynamics damping="1" friction="0" />
  </joint>
  <joint name="base_l_passive_wheel_x_frame_joint" type="continuous">
    <parent link="base_roll_link"/>
    <child  link="base_l_passive_wheel_x_frame"/>
    <origin xyz="0.1495 0.055 0.03" rpy="0 -0 0 "/>
    <axis   xyz="1 0 0"/>
    <limit lower="0" upper="0" effort="1" velocity="3" />
    <dynamics damping="1" friction="0" />
  </joint>
  <joint name="base_l_passive_wheel_y_frame_joint" type="continuous">
    <parent link="base_l_passive_wheel_x_frame"/>
    <child  link="base_l_passive_wheel_y_frame"/>
    <origin xyz="0 0 0" rpy="0 -0 0 "/>
    <axis   xyz="0 1 0"/>
    <limit lower="0" upper="0" effort="8.85" velocity="10" />
    <dynamics damping="0.2" friction="0" />
  </joint>
  <joint name="base_l_passive_wheel_z_joint" type="continuous">
    <parent link="base_l_passive_wheel_y_frame"/>
    <child  link="base_l_passive_wheel_z_link"/>
    <origin xyz="0 0 0" rpy="0 -0 0 "/>
    <axis   xyz="0 0 1"/>
    <limit lower="0" upper="0" effort="8.85" velocity="10" />
    <dynamics damping="0.2" friction="0" />
  </joint>
  <joint name="base_r_drive_wheel_joint" type="continuous">
    <parent link="base_roll_link"/>
    <child  link="base_r_drive_wheel_link"/>
    <origin xyz="-0.11 -0.133 0.04" rpy="0 -0 0 "/>
    <axis   xyz="0 1 0"/>
    <limit lower="0" upper="0" effort="11.067" velocity="20.8" />
    <dynamics damping="1" friction="0" />
  </joint>
  <joint name="base_r_passive_wheel_x_frame_joint" type="continuous">
    <parent link="base_roll_link"/>
    <child  link="base_r_passive_wheel_x_frame"/>
    <origin xyz="0.1495 -0.055 0.03" rpy="0 -0 0 "/>
    <axis   xyz="1 0 0"/>
    <limit lower="0" upper="0" effort="1" velocity="3" />
    <dynamics damping="1" friction="0" />
  </joint>
  <joint name="base_r_passive_wheel_y_frame_joint" type="continuous">
    <parent link="base_r_passive_wheel_x_frame"/>
    <child  link="base_r_passive_wheel_y_frame"/>
    <origin xyz="0 0 0" rpy="0 -0 0 "/>
    <axis   xyz="0 1 0"/>
    <limit lower="0" upper="0" effort="8.85" velocity="10" />
    <dynamics damping="0.2" friction="0" />
  </joint>
  <joint name="base_r_passive_wheel_z_joint" type="continuous">
    <parent link="base_r_passive_wheel_y_frame"/>
    <child  link="base_r_passive_wheel_z_link"/>
    <origin xyz="0 0 0" rpy="0 -0 0 "/>
    <axis   xyz="0 0 1"/>
    <limit lower="0" upper="0" effort="8.85" velocity="10" />
    <dynamics damping="0.2" friction="0" />
  </joint>
  <joint name="torso_lift_joint" type="prismatic">
    <parent link="base_link"/>
    <child  link="torso_lift_link"/>
    <origin xyz="0 0 0.752" rpy="0 -0 0 "/>
    <axis   xyz="0 0 1"/>
    <limit lower="0" upper="0.345" effort="300" velocity="0.1" />
    <dynamics damping="500" friction="0" />
  </joint>
  <joint name="head_pan_joint" type="revolute">
    <parent link="torso_lift_link"/>
    <child  link="head_pan_link"/>
    <origin xyz="0 0 0" rpy="0 -0 0 "/>
    <axis   xyz="0 0 1"/>
    <limit lower="-3.84" upper="1.75" effort="100" velocity="1" />
    <dynamics damping="1" friction="0" />
  </joint>
  <joint name="head_tilt_joint" type="revolute">
    <parent link="head_pan_link"/>
    <child  link="head_tilt_link"/>
    <origin xyz="0.02 0 0" rpy="0 -0 0 "/>
    <axis   xyz="0 -1 0"/>
    <limit lower="-1.57" upper="0.52" effort="100" velocity="1" />
    <dynamics damping="10" friction="0" />
  </joint>
  <joint name="head_center_camera_frame_joint" type="fixed">
    <parent link="head_tilt_link"/>
    <child  link="head_center_camera_frame"/>
    <origin xyz="0.0195 0 0.061" rpy="-1.5708 -5.55112e-17 -1.5708 "/>
    <axis   xyz="0 0 0"/>
    <dynamics damping="0.2" friction="0" />
  </joint>
  <joint name="head_center_camera_gazebo_frame_joint" type="fixed">
    <parent link="head_center_camera_frame"/>
    <child  link="head_center_camera_gazebo_frame"/>
    <origin xyz="0 0 0" rpy="0 -1.5708 1.5708 "/>
    <axis   xyz="0 0 0"/>
    <dynamics damping="0.2" friction="0" />
  </joint>
  <joint name="head_l_stereo_camera_joint" type="fixed">
    <parent link="head_tilt_link"/>
    <child  link="head_l_stereo_camera_link"/>
    <origin xyz="0.02 0.07 0.061" rpy="-1.5708 -5.55112e-17 -1.5708 "/>
    <axis   xyz="0 0 0"/>
    <dynamics damping="0.2" friction="0" />
  </joint>
  <joint name="head_l_stereo_camera_gazebo_frame_joint" type="fixed">
    <parent link="head_l_stereo_camera_link"/>
    <child  link="head_l_stereo_camera_gazebo_frame"/>
    <origin xyz="0 0 0" rpy="0 -1.5708 1.5708 "/>
    <axis   xyz="0 0 0"/>
    <dynamics damping="0.2" friction="0" />
  </joint>
  <joint name="head_r_stereo_camera_joint" type="fixed">
    <parent link="head_tilt_link"/>
    <child  link="head_r_stereo_camera_link"/>
    <origin xyz="0.02 -0.07 0.061" rpy="-1.5708 -5.55112e-17 -1.5708 "/>
    <axis   xyz="0 0 0"/>
    <dynamics damping="0.2" friction="0" />
  </joint>
  <joint name="head_r_stereo_camera_gazebo_frame_joint" type="fixed">
    <parent link="head_r_stereo_camera_link"/>
    <child  link="head_r_stereo_camera_gazebo_frame"/>
    <origin xyz="0 0 0" rpy="0 -1.5708 1.5708 "/>
    <axis   xyz="0 0 0"/>
    <dynamics damping="0.2" friction="0" />
  </joint>
  <joint name="head_rgbd_sensor_joint" type="fixed">
    <parent link="head_tilt_link"/>
    <child  link="head_rgbd_sensor_link"/>
    <origin xyz="-0.079796 0.022 0.215172" rpy="-1.5708 -5.55112e-17 -1.5708 "/>
    <axis   xyz="0 0 0"/>
    <dynamics damping="0.2" friction="0" />
  </joint>
  <joint name="head_rgbd_sensor_gazebo_frame_joint" type="fixed">
    <parent link="head_rgbd_sensor_link"/>
    <child  link="head_rgbd_sensor_gazebo_frame"/>
    <origin xyz="0 0 0" rpy="0 -1.5708 1.5708 "/>
    <axis   xyz="0 0 0"/>
    <dynamics damping="0.2" friction="0" />
  </joint>
</robot>
